[2025-06-25T18:04:06.895+0000] {taskinstance.py:1159} INFO - Dependencies all met for dep_context=non-requeueable deps ti=<TaskInstance: etl_reddit_pipeline.s3_upload manual__2025-06-25T18:04:01.314682+00:00 [queued]>
[2025-06-25T18:04:06.901+0000] {taskinstance.py:1159} INFO - Dependencies all met for dep_context=requeueable deps ti=<TaskInstance: etl_reddit_pipeline.s3_upload manual__2025-06-25T18:04:01.314682+00:00 [queued]>
[2025-06-25T18:04:06.901+0000] {taskinstance.py:1361} INFO - Starting attempt 1 of 1
[2025-06-25T18:04:06.908+0000] {taskinstance.py:1382} INFO - Executing <Task(PythonOperator): s3_upload> on 2025-06-25 18:04:01.314682+00:00
[2025-06-25T18:04:06.912+0000] {standard_task_runner.py:57} INFO - Started process 174 to run task
[2025-06-25T18:04:06.916+0000] {standard_task_runner.py:84} INFO - Running: ['airflow', 'tasks', 'run', 'etl_reddit_pipeline', 's3_upload', 'manual__2025-06-25T18:04:01.314682+00:00', '--job-id', '32', '--raw', '--subdir', 'DAGS_FOLDER/reddit_dag.py', '--cfg-path', '/tmp/tmpum2cgsk3']
[2025-06-25T18:04:06.919+0000] {standard_task_runner.py:85} INFO - Job 32: Subtask s3_upload
[2025-06-25T18:04:06.959+0000] {task_command.py:416} INFO - Running <TaskInstance: etl_reddit_pipeline.s3_upload manual__2025-06-25T18:04:01.314682+00:00 [running]> on host f892d2298fb9
[2025-06-25T18:04:07.016+0000] {taskinstance.py:1662} INFO - Exporting env vars: AIRFLOW_CTX_DAG_OWNER='Paresh Jadhav' AIRFLOW_CTX_DAG_ID='etl_reddit_pipeline' AIRFLOW_CTX_TASK_ID='s3_upload' AIRFLOW_CTX_EXECUTION_DATE='2025-06-25T18:04:01.314682+00:00' AIRFLOW_CTX_TRY_NUMBER='1' AIRFLOW_CTX_DAG_RUN_ID='manual__2025-06-25T18:04:01.314682+00:00'
[2025-06-25T18:04:07.018+0000] {taskinstance.py:1937} ERROR - Task failed with exception
Traceback (most recent call last):
  File "/home/airflow/.local/lib/python3.9/site-packages/airflow/operators/python.py", line 192, in execute
    return_value = self.execute_callable()
  File "/home/airflow/.local/lib/python3.9/site-packages/airflow/operators/python.py", line 209, in execute_callable
    return self.python_callable(*self.op_args, **self.op_kwargs)
  File "/opt/airflow/pipelines/aws_s3_pipline.py", line 6, in upload_s3_pipeline
    file_path = ti.xcom_pull(task_id='reddit_extraction', key='return value')
  File "/home/airflow/.local/lib/python3.9/site-packages/airflow/utils/session.py", line 77, in wrapper
    return func(*args, session=session, **kwargs)
TypeError: xcom_pull() got an unexpected keyword argument 'task_id'
[2025-06-25T18:04:07.028+0000] {taskinstance.py:1400} INFO - Marking task as FAILED. dag_id=etl_reddit_pipeline, task_id=s3_upload, execution_date=20250625T180401, start_date=20250625T180406, end_date=20250625T180407
[2025-06-25T18:04:07.036+0000] {standard_task_runner.py:104} ERROR - Failed to execute job 32 for task s3_upload (xcom_pull() got an unexpected keyword argument 'task_id'; 174)
[2025-06-25T18:04:07.048+0000] {local_task_job_runner.py:228} INFO - Task exited with return code 1
[2025-06-25T18:04:07.062+0000] {taskinstance.py:2778} INFO - 0 downstream tasks scheduled from follow-on schedule check
