[2025-06-25T18:05:30.926+0000] {taskinstance.py:1159} INFO - Dependencies all met for dep_context=non-requeueable deps ti=<TaskInstance: etl_reddit_pipeline.s3_upload manual__2025-06-25T18:05:25.427358+00:00 [queued]>
[2025-06-25T18:05:30.932+0000] {taskinstance.py:1159} INFO - Dependencies all met for dep_context=requeueable deps ti=<TaskInstance: etl_reddit_pipeline.s3_upload manual__2025-06-25T18:05:25.427358+00:00 [queued]>
[2025-06-25T18:05:30.933+0000] {taskinstance.py:1361} INFO - Starting attempt 1 of 1
[2025-06-25T18:05:30.939+0000] {taskinstance.py:1382} INFO - Executing <Task(PythonOperator): s3_upload> on 2025-06-25 18:05:25.427358+00:00
[2025-06-25T18:05:30.944+0000] {standard_task_runner.py:57} INFO - Started process 180 to run task
[2025-06-25T18:05:30.948+0000] {standard_task_runner.py:84} INFO - Running: ['airflow', 'tasks', 'run', 'etl_reddit_pipeline', 's3_upload', 'manual__2025-06-25T18:05:25.427358+00:00', '--job-id', '34', '--raw', '--subdir', 'DAGS_FOLDER/reddit_dag.py', '--cfg-path', '/tmp/tmposqui26m']
[2025-06-25T18:05:30.950+0000] {standard_task_runner.py:85} INFO - Job 34: Subtask s3_upload
[2025-06-25T18:05:30.983+0000] {task_command.py:416} INFO - Running <TaskInstance: etl_reddit_pipeline.s3_upload manual__2025-06-25T18:05:25.427358+00:00 [running]> on host f892d2298fb9
[2025-06-25T18:05:31.029+0000] {taskinstance.py:1662} INFO - Exporting env vars: AIRFLOW_CTX_DAG_OWNER='Paresh Jadhav' AIRFLOW_CTX_DAG_ID='etl_reddit_pipeline' AIRFLOW_CTX_TASK_ID='s3_upload' AIRFLOW_CTX_EXECUTION_DATE='2025-06-25T18:05:25.427358+00:00' AIRFLOW_CTX_TRY_NUMBER='1' AIRFLOW_CTX_DAG_RUN_ID='manual__2025-06-25T18:05:25.427358+00:00'
[2025-06-25T18:05:31.039+0000] {taskinstance.py:1937} ERROR - Task failed with exception
Traceback (most recent call last):
  File "/opt/airflow/etls/aws_etl.py", line 11, in connect_to_s3
    s3 = s3fs.s3FileSystem(anon=False,key=AWS_ACCESS_KEY,secret =AWS_SECRET_KEY)
AttributeError: module 's3fs' has no attribute 's3FileSystem'

During handling of the above exception, another exception occurred:

Traceback (most recent call last):
  File "/home/airflow/.local/lib/python3.9/site-packages/airflow/operators/python.py", line 192, in execute
    return_value = self.execute_callable()
  File "/home/airflow/.local/lib/python3.9/site-packages/airflow/operators/python.py", line 209, in execute_callable
    return self.python_callable(*self.op_args, **self.op_kwargs)
  File "/opt/airflow/pipelines/aws_s3_pipline.py", line 7, in upload_s3_pipeline
    s3 = connect_to_s3()
  File "/opt/airflow/etls/aws_etl.py", line 14, in connect_to_s3
    logger.error(e.with_traceback())
TypeError: BaseException.with_traceback() takes exactly one argument (0 given)
[2025-06-25T18:05:31.047+0000] {taskinstance.py:1400} INFO - Marking task as FAILED. dag_id=etl_reddit_pipeline, task_id=s3_upload, execution_date=20250625T180525, start_date=20250625T180530, end_date=20250625T180531
[2025-06-25T18:05:31.053+0000] {standard_task_runner.py:104} ERROR - Failed to execute job 34 for task s3_upload (BaseException.with_traceback() takes exactly one argument (0 given); 180)
[2025-06-25T18:05:31.080+0000] {local_task_job_runner.py:228} INFO - Task exited with return code 1
[2025-06-25T18:05:31.092+0000] {taskinstance.py:2778} INFO - 0 downstream tasks scheduled from follow-on schedule check
